Workbook

Sheet Executive Summary
B2: SG RESIDENTIAL PROPERTY · CONSULTATION REPORT 2026
B3: Property Consultation Report
B5: Client Name | C5: Sample Client
B6: Report Date | C6: 10 April 2026
B7: Advisor | C7: Chester
B8: Primary Goal | C8: Sell HDB → Buy Condo
B9: Budget Ceiling | C9: 1400000
B11: FINANCIAL SNAPSHOT
B12: Total Gross Income (Monthly) | C12: ='Client Profile'!C14 -> 11279
B13: Total Funds Available | C13: ='Client Profile'!C36 -> 827000
B14: Max Affordable Price | C14: ='Client Profile'!C40 -> 0
B15: TDSR Headroom ($/mo) | C15: ='Client Profile'!C41 -> 1730000
B16: Budget Check | C16: =IF(C9<='Client Profile'!C40,"WITHIN RANGE","EXCEEDS MAX") -> EXCEEDS MAX
B18: ADVISOR RECOMMENDATION
B19: [Enter recommendation summary here — e.g., Based on your financial profile and goals, we recommend selling your HDB and purchasing a private condo in the $1.35-1.40M range. The Antares at Mattar offers the best yield-carry balance, while Rivercove Residences provides stronger capital gain potential.]
B22: TOP 3 SHORTLISTED PROPERTIES
A23: # | B23: # | C23: Project | D23: Price (Mid) | E23: Gross Yield | F23: Monthly Carry | G23: Base IRR (5yr)
B24: 1 | C24: Rivercove Residences | D24: 1390000 | E24: =3800*12/1390000 -> 0.032805755 | F24: =3800*0.9-PMT(0.038/12,360,-1390000*0.75)-380-3800*0.85*0.11 -> -2172.9054 | G24: See Deep Dive
B25: 2 | C25: The Antares | D25: 1375000 | E25: =4200*12/1375000 -> 0.036654545 | F25: =4200*0.9-PMT(0.038/12,360,-1375000*0.75)-380-4200*0.85*0.11 -> -1797.8852 | G25: See Deep Dive
B26: 3 | C26: ECO at Bedok | D26: 1210000 | E26: =3900*12/1210000 -> 0.038677686 | F26: =3900*0.9-PMT(0.038/12,360,-1210000*0.75)-380-3900*0.85*0.11 -> -1463.213 | G26: See Deep Dive

Sheet Client Profile
B2: CLIENT PROFILE & FINANCIAL POSITION
B4: A) CLIENT IDENTITY
B5: Client Name | C5: Sample Client
B6: Residency Status | C6: SC
B7: Age | C7: 35
B8: Age Bracket | C8: <=35
B9: Marital Status | C9: Married
B10: B) INCOME & EMPLOYMENT
B11: Gross Monthly Income (Applicant A) | C11: 11279
B12: Gross Monthly Income (Applicant B) | C12: 0
B13: Additional Income (non-TDSR) | C13: 4500
B14: Total Gross Income (TDSR-eligible) | C14: =C11+C12 -> 11279
B15: CPF Contribution Rate | C15: 0.37
B16: CPF OA Ratio | C16: 0.6217
B17: CPF OA Monthly Inflow | C17: =C11*C15*C16 -> 2594.4971
B18: Employee CPF Rate | C18: 0.2
B19: Net Take-Home (A+B+Additional) | C19: =C11*(1-C18)+C12*(1-C18)+C13 -> 13523.2
B20: C) EXISTING COMMITMENTS
B21: Car Loan / Personal Loan (monthly) | C21: 0
B22: Other Monthly Commitments | C22: 0
B23: Total Commitments | C23: =C21+C22 -> 0
B24: D) CURRENT PROPERTY
B25: Currently Owns Property? | C25: Yes
B26: Property Type | C26: HDB 4-Room
B27: District | C27: D19 Sengkang
B28: Est. Market Value | C28: 650000
B29: Outstanding Mortgage | C29: 180000
B30: Monthly Mortgage Payment | C30: 1200
B31: Net Equity | C31: =IF(C25="Yes",C28-C29,0) -> 470000
B32: Est. Sale Proceeds (net 2% agent) | C32: =IF(C25="Yes",C28-C29-C28*0.02,0) -> 457000
B33: E) AVAILABLE FUNDS
B34: CPF OA Balance (Applicant A) | C34: 120000
B35: CPF OA Balance (Applicant B) | C35: 0
B36: Total Funds (CPF+Cash+Liquid+SaleProceeds) | C36: =C34+C35+C37+C38+C39+IF(C32>0,C32,0) -> 827000
B37: Cash Savings | C37: 200000
B38: Other Liquid Assets | C38: 50000
B39: Gift / Family Support | C39: 0
B40: F) AFFORDABILITY ANALYSIS
B41: Max Affordable Price | C41: =IF(C14>0,ROUND((C14*0.55-C23)/0.004774/0.75,-4),0) -> 1730000
B42: TDSR Headroom ($/mo) | C42: =C14*0.55-C23 -> 6203.45
...

Sheet Scenario Comparison
B2: SCENARIO COMPARISON
B4: Metric | C4: A: Status Quo | D4: B: Sell → Buy Condo | E4: C: Buy Investment
B5: Action | C5: Stay in current property | D5: Sell HDB, buy private condo | E5: Keep HDB, buy investment condo
B6: Purchase Price | C6: N/A | D6: ='Client Profile'!C46 -> 1400000 | E6: =1375000 -> 1375000
B7: BSD (tiered) | C7: N/A | D7: =MIN('Client Profile'!C46,180000)*0.01+MIN(MAX('Client Profile'!C46-180000,0),180000)*0.02+MIN(MAX('Client Profile'!C46-360000,0),640000)*0.03+MIN(MAX('Client Profile'!C46-1000000,0),500000)*0.04+MIN(MAX('Client Profile'!C46-1500000,0),1500000)*0.05+MAX('Client Profile'!C46-3000000,0)*0.06 -> 40600 | E7: =MIN(1375000,180000)*0.01+MIN(MAX(1375000-180000,0),180000)*0.02+MIN(MAX(1375000-360000,0),640000)*0.03+MIN(MAX(1375000-1000000,0),500000)*0.04 -> 39600
B8: ABSD (SC 1st property) | C8: N/A | D8: =0 -> 0 | E8: =0 -> 0
B9: Downpayment (25%) | C9: N/A | D9: =D6*0.25 -> 350000 | E9: =E6*0.25 -> 343750
B10: Legal Fees | C10: N/A | D10: =3800 -> 3800 | E10: =3800 -> 3800
B11: Reno & Furnishing | C11: N/A | D11: =0 -> 0 | E11: =20000 -> 20000
B12: Total Upfront Cash | C12: N/A | D12: =D7+D8+D9+D10+D11 -> 394400 | E12: =E7+E8+E9+E10+E11 -> 407150
B13: Loan Amount (75% LTV) | C13: N/A | D13: =D6*0.75 -> 1050000 | E13: =E6*0.75 -> 1031250
B14: Monthly Mortgage (P+I) | C14: N/A | D14: =PMT(0.015/12,360,-D13) -> 3623.7622 | E14: =PMT(0.038/12,360,-E13) -> 4805.1852
B15: CPF OA Monthly Coverage | C15: ='Client Profile'!C17 -> 2594.4971 | D15: =MIN('Client Profile'!C17,D14) -> 2594.4971 | E15: =0 -> 0
B16: Cash Outlay per Month | C16: =0 -> 0 | D16: =MAX(0,D14-D15) -> 1029.2651 | E16: =E14 -> 4805.1852
B17: TDSR Check | C17: N/A | D17: =IF('Client Profile'!C14>0,D14/'Client Profile'!C14,0) -> 0.321284 | E17: =IF('Client Profile'!C14>0,(E14+'Client Profile'!C30)/'Client Profile'!C14,0) -> 0.53242177
B18: Gross Rental Income | C18: N/A | D18: N/A | E18: =4200 -> 4200
B19: Occupancy-Adj Rent (90%) | C19: N/A | D19: N/A | E19: =E18*0.9 -> 3780
B20: Maintenance + Prop Tax | C20: N/A | D20: N/A | E20: =380+E18*0.85*0.11 -> 772.7
B21: Net Monthly Carry | C21: N/A | D21: =0-D14 -> -3623.7622 | E21: =E19-E14-E20 -> -1797.8852
B22: Surplus / Shortfall (Funds) | C22: N/A | D22: ='Client Profile'!C36-D12 -> 432600 | E22: =('Client Profile'!C34+'Client Profile'!C35+'Client Profile'!C37+'Client Profile'!C38)-E12 -> -37150
B23: Est. Property Value (5yr) | C23: =IF('Client Profile'!C25="Yes",'Client Profile'!C28*1.02^5,0) -> 717652.52 | D23: =D6*1.04^5 -> 1703314.1 | E23: =E6*1.04^5 -> 1672897.7
B24: Remaining Loan (5yr) | C24: N/A | D24: =D13*((1+0.015/12)^360-(1+0.015/12)^60)/((1+0.015/12)^360-1) -> 906084.79 | E24: =E13*((1+0.038/12)^360-(1+0.038/12)^60)/((1+0.038/12)^360-1) -> 929694.14
B25: Est. Exit Equity (5yr) | C25: N/A | D25: =D23-D24-D23*0.01 -> 780196.14 | E25: =E23-E24-E23*0.01 -> 726474.62
B27: PROS & CONS SUMMARY
B28: Advantages | C28: No cost, no disruption | D28: Zero ABSD, equity unlock | E28: Zero ABSD, rental income, diversify
B29: Risks / Trade-offs | C29: Locked equity, opportunity cost | D29: Transaction costs, market risk | E29: Negative carry, TDSR load, dual mortgage

Sheet Property Shortlist
B2: PROPERTY SHORTLIST — TOP 5 RECOMMENDATIONS
B4: Project | C4: Dist | D4: Type | E4: Budget Min | F4: Budget Max | G4: PSF | H4: Rent/mo | I4: Gross Yield | J4: Monthly Carry | K4: Base IRR | L4: Priority | M4: Investment Thesis
B5: Rivercove Residences | C5: D19 | D5: Post-MOP EC | E5: 1350000 | F5: 1430000 | G5: 1615 | H5: 3800 | I5: =H5*12/((E5+F5)/2) -> 0.032805755 | J5: =H5*0.9-PMT(0.038/12,360,-((E5+F5)/2)*0.75)-380-H5*0.85*0.11 -> -2172.9054 | K5: See Deep Dive | L5: PRIMARY | M5: Freshly MOP'd EC — waterfront on Punggol Reservoir. Hundred Palms trajectory template.
B6: The Antares | C6: D14 | D6: Private Resale | E6: 1350000 | F6: 1400000 | G6: 2067 | H6: 4200 | I6: =H6*12/((E6+F6)/2) -> 0.036654545 | J6: =H6*0.9-PMT(0.038/12,360,-((E6+F6)/2)*0.75)-380-H6*0.85*0.11 -> -1797.8852 | K6: See Deep Dive | L6: PRIMARY | M6: Highest yield. 1-min sheltered Mattar MRT DTL. Bidadari + Paya Lebar + Geylang rezoning catalysts.
B7: ECO at Bedok | C7: D16 | D7: Private Resale | E7: 1080000 | F7: 1340000 | G7: 1549 | H7: 3900 | I7: =H7*12/((E7+F7)/2) -> 0.038677686 | J7: =H7*0.9-PMT(0.038/12,360,-((E7+F7)/2)*0.75)-380-H7*0.85*0.11 -> -1463.213 | K7: See Deep Dive | L7: SECONDARY | M7: TEL Bedok South 2026 — dual-line access. Best yield-per-dollar on shortlist.
B8: Treasure at Tampines | C8: D18 | D8: Private Resale | E8: 1190000 | F8: 1270000 | G8: 1700 | H8: 3600 | I8: =H8*12/((E8+F8)/2) -> 0.035121951 | J8: =H8*0.9-PMT(0.038/12,360,-((E8+F8)/2)*0.75)-380-H8*0.85*0.11 -> -1775.0566 | K8: See Deep Dive | L8: SECONDARY | M8: Deepest resale liquidity — 170 units in 2025. Changi Biz Park tenant base.
B9: Florence Residences | C9: D19 | D9: Private Resale | E9: 1200000 | F9: 1400000 | G9: 1800 | H9: 3500 | I9: =H9*12/((E9+F9)/2) -> 0.032307692 | J9: =H9*0.9-PMT(0.038/12,360,-((E9+F9)/2)*0.75)-380-H9*0.85*0.11 -> -2100.3342 | K9: See Deep Dive | L9: SECONDARY | M9: Newer private in D19 with Hougang MRT NEL. Same district demand as Rivercove.

Sheet Deep Dive — Rivercove
B2: DEEP DIVE — RIVERCOVE RESIDENCES
B3: Post-MOP EC · D19 Sengkang · 3BR/2BA · 904-958 sqft · 99yr
B5: KEY INPUTS
B6: Purchase Price (midpoint) | C6: 1390000
B7: Monthly Rent Estimate | C7: 3800
B8: Mortgage Rate (Investment) | C8: 0.038
B9: Loan Tenure (years) | C9: 30
B10: LTV Ratio | C10: 0.75
B11: Residency | C11: SC
B12: Property Count (before purchase) | C12: 0
B14: ACQUISITION COST BREAKDOWN
B15: Purchase Price | C15: =C6 -> 1390000
B16: Buyer Stamp Duty (BSD) | C16: =MIN(C6,180000)*0.01+MIN(MAX(C6-180000,0),180000)*0.02+MIN(MAX(C6-360000,0),640000)*0.03+MIN(MAX(C6-1000000,0),500000)*0.04+MIN(MAX(C6-1500000,0),1500000)*0.05+MAX(C6-3000000,0)*0.06 -> 40200
B17: ABSD | C17: =IF(C11="SC",IF(C12=0,0,IF(C12=1,C6*0.2,C6*0.35)),IF(C11="PR",IF(C12=0,C6*0.05,IF(C12=1,C6*0.3,C6*0.35)),C6*0.6)) -> 0
B18: Legal Fees | C18: 3800
B19: Reno & Furnishing | C19: 20000
B20: Downpayment | C20: =C6*(1-C10) -> 347500
B21: TOTAL UPFRONT CASH | C21: =C16+C17+C18+C19+C20 -> 411500
B22: Loan Amount | C22: =C6*C10 -> 1042500
B24: MONTHLY CASH FLOW (YEAR 1)
B25: Gross Monthly Rent | C25: =C7 -> 3800
B26: Occupancy-Adjusted (90%) | C26: =C7*0.9 -> 3420
B27: Monthly Mortgage (P+I) | C27: =PMT(C8/12,C9*12,-C22) -> 4857.6054
B28: Maintenance (est.) | C28: 380
B29: Property Tax (NROC est.) | C29: =C7*0.85*0.11 -> 355.3
B30: NET MONTHLY CARRY | C30: =C26-C27-C28-C29 -> -2172.9054
B31: Gross Yield | C31: =C7*12/C6 -> 0.032805755
B32: Annual Carry | C32: =C30*12 -> -26074.865
B33: 5-Year Carry Reserve Needed | C33: =IF(C30<0,ABS(C30)*60,0) -> 130374.32
B35: EXIT SCENARIOS (YEAR 5)
B36: Metric | C36: Bear Case | D36: Base Case | E36: Bull Case
B37: Capital CAGR | C37: 0.02 | D37: 0.04 | E37: 0.06
B38: Exit Price | C38: =C6*(1+C37)^5 -> 1534672.3 | D38: =C6*(1+D37)^5 -> 1691147.5 | E38: =C6*(1+E37)^5 -> 1860133.6
B39: Remaining Loan (5yr) | C39: =C22*((1+C8/12)^(C9*12)-(1+C8/12)^60)/((1+C8/12)^(C9*12)-1) -> 939836.26 | D39: =C22*((1+C8/12)^(C9*12)-(1+C8/12)^60)/((1+C8/12)^(C9*12)-1) -> 939836.26 | E39: =C22*((1+C8/12)^(C9*12)-(1+C8/12)^60)/((1+C8/12)^(C9*12)-1) -> 939836.26
B40: Agent Commission (1%) | C40: =C38*0.01 -> 15346.723 | D40: =D38*0.01 -> 16911.475 | E40: =E38*0.01 -> 18601.336
B41: Exit Equity | C41: =C38-C39-C40 -> 579489.33 | D41: =D38-D39-D40 -> 734399.8 | E41: =E38-E39-E40 -> 901695.96
B42: Equity IRR (5yr) | C42: =IFERROR(IRR(C51:H51),0) -> 0.01575017 | D42: =IFERROR(IRR(C52:H52),0) -> 0.072425959 | E42: =IFERROR(IRR(C53:H53),0) -> 0.12302436
B43: Meets Target IRR? | C43: =IF(C42>='Client Profile'!C52,"YES — MEETS TARGET","BELOW TARGET") -> BELOW TARGET | D43: =IF(D42>='Client Profile'!C52,"YES — MEETS TARGET","BELOW TARGET") -> BELOW TARGET | E43: =IF(E42>='Client Profile'!C52,"YES — MEETS TARGET","BELOW TARGET") -> YES — MEETS TARGET
B45: INVESTMENT THESIS & NOTES
B46: Freshly MOP'd Oct 2025. EC-to-private price gap fully intact. Waterfront on Punggol Reservoir. Hundred Palms trajectory is the template. Key catalysts: EC price discovery phase, waterfront reservoir facing, PDD adjacency, school cluster. Risks: LRT dependency (not direct MRT), D19 supply pipeline, 3.0% yield = higher carry.
...
